<?xml version="1.0" ?>
<!-- =================================================================================== -->
<!-- |    This document was autogenerated by xacro from /media/ros/fedora/home/maylis/Dokumente/TeleNav/simulation_ws/src/my_robot_description/urdf/robot.urdf.xacro | -->
<!-- |    EDITING THIS FILE BY HAND IS NOT RECOMMENDED                                 | -->
<!-- =================================================================================== -->
<robot name="robot">
  <!--Defines a material that can be used to color a geometry-->
  <material name="green">
    <color rgba="0 0.5 0 1"/>
    <!-- green color in rgba-->
  </material>
  <material name="blue">
    <color rgba="0 0 0.5 1"/>
    <!-- blue color in rgba-->
  </material>
  <material name="grey">
    <color rgba="0.5 0.5 0.5 1"/>
    <!-- green color in rgba-->
  </material>
  <link name="right_wheel_link">
    <visual>
      <origin rpy="1.5707963267948966 0 0" xyz="0 0 0"/>
      <geometry>
        <cylinder length="0.05" radius="0.1"/>
        <!-- in meters |  20cm radius | 20cm height -->
      </geometry>
      <material name="grey"/>
    </visual>
    <collision>
      <origin rpy="1.5707963267948966 0 0" xyz="0 0 0"/>
      <geometry>
        <cylinder length="0.05" radius="0.1"/>
        <!-- in meters |  20cm radius | 20cm height -->
      </geometry>
    </collision>
    <intertial>
      <origin rpy="0 0 0" xyz="0 0 0"/>
      <mass value="1"/>
      <inertia ixx="0.002708333333333334" ixy="0" ixz="0" iyx="0" iyy="0.002708333333333334" iyz="0" izx="0" izy="0" izz="0.005000000000000001"/>
    </intertial>
  </link>
  <link name="left_wheel_link">
    <visual>
      <origin rpy="1.5707963267948966 0 0" xyz="0 0 0"/>
      <geometry>
        <cylinder length="0.05" radius="0.1"/>
        <!-- in meters |  20cm radius | 20cm height -->
      </geometry>
      <material name="grey"/>
    </visual>
    <collision>
      <origin rpy="1.5707963267948966 0 0" xyz="0 0 0"/>
      <geometry>
        <cylinder length="0.05" radius="0.1"/>
        <!-- in meters |  20cm radius | 20cm height -->
      </geometry>
    </collision>
    <intertial>
      <origin rpy="0 0 0" xyz="0 0 0"/>
      <mass value="1"/>
      <inertia ixx="0.002708333333333334" ixy="0" ixz="0" iyx="0" iyy="0.002708333333333334" iyz="0" izx="0" izy="0" izz="0.005000000000000001"/>
    </intertial>
  </link>
  <link name="base_footprint">
    <visual>
      <origin rpy="0 0 0" xyz="0 0 0"/>
      <geometry>
        <box size="0 0 0"/>
      </geometry>
      <collision>
        <origin rpy="0 0 0" xyz="0 0 0"/>
        <geometry>
          <box size="0 0 0"/>
        </geometry>
      </collision>
      <material name="green"/>
      <intertial>
        <origin rpy="0 0 0" xyz="0 0 0"/>
        <mass value="0.01"/>
        <inertia ixx="0.0" ixy="0" ixz="0" iyx="0" iyy="0.0" iyz="0" izx="0" izy="0" izz="0.0"/>
      </intertial>
    </visual>
  </link>
  <joint name="footprint_to_base_link_joint" type="fixed">
    <parent link="base_footprint"/>
    <child link="base_link"/>
    <origin rpy="0 0 0" xyz="0 0 0.1"/>
  </joint>
  <!-- Defines the geometry and link of the robot-->
  <link name="base_link">
    <!-- The base link is nessesary as a basic link object-->
    <visual>
      <!-- Places the robot on the default position -->
      <origin rpy="0 0 0" xyz="0 0 0.1"/>
      <!-- position of the box rpy toll pitch yaw-->
      <geometry>
        <box size="0.6 0.4 0.2"/>
        <!-- in meters |  60cm long | 40cm wide | 20 cm high -->
      </geometry>
      <material name="blue"/>
      <!-- color of the box -->
    </visual>
    <collision>
      <geometry>
        <box size="0.6 0.4 0.2"/>
        <!-- in meters |  60cm long | 40cm wide | 20 cm high -->
      </geometry>
      <origin rpy="0 0 0" xyz="0 0 0.1"/>
    </collision>
    <intertial>
      <origin rpy="0 0 0" xyz="0 0 0.1"/>
      <mass value="5.0"/>
      <inertia ixx="0.08333333333333336" ixy="0" ixz="0" iyx="0" iyy="0.16666666666666669" iyz="0" izx="0" izy="0" izz="0.21666666666666667"/>
    </intertial>
  </link>
  <joint name="base_right_wheel_joint" type="continuous">
    <parent link="base_link"/>
    <child link="right_wheel_link"/>
    <origin rpy="0 0 0" xyz="-0.15 -0.2 0"/>
    <axis xyz="0 1 0"/>
  </joint>
  <joint name="base_left_wheel_joint" type="continuous">
    <parent link="base_link"/>
    <child link="left_wheel_link"/>
    <origin rpy="0 0 0" xyz="-0.15 0.2 0"/>
    <axis xyz="0 1 0"/>
  </joint>
  <link name="caster_wheel_link">
    <visual>
      <origin rpy="0 0 0" xyz="0 0 0"/>
      <geometry>
        <sphere radius="0.05"/>
        <!-- in meters |  20cm radius | 20cm height -->
      </geometry>
      <material name="grey"/>
    </visual>
    <intertial>
      <origin rpy="0 0 0" xyz="0 0 0"/>
      <mass value="0.5"/>
      <inertia ixx="0.0005000000000000001" ixy="0" ixz="0" iyx="0" iyy="0.0005000000000000001" iyz="0" izx="0" izy="0" izz="0.0005000000000000001"/>
    </intertial>
    <collision>
      <origin rpy="0 0 0" xyz="0 0 0"/>
      <geometry>
        <sphere radius="0.05"/>
        <!-- in meters |  20cm radius | 20cm height -->
      </geometry>
    </collision>
  </link>
  <joint name="base_caster_wheel_joint" type="continuous">
    <parent link="base_link"/>
    <child link="caster_wheel_link"/>
    <origin rpy="0 0 0" xyz="0.19999999999999998 0 -0.05"/>
    <axis xyz="0 1 0"/>
  </joint>
  <gazebo reference="right_wheel_link">
    <mu1>0.9</mu1>
    <mu2>0.9</mu2>
  </gazebo>
  <gazebo reference="left_wheel_link">
    <mu1>0.9</mu1>
    <mu2>0.9</mu2>
  </gazebo>
  <gazebo reference="caster_wheel_link">
    <mu1>0.2</mu1>
    <mu2>0.2</mu2>
  </gazebo>
  <gazebo reference="base_link">
    <material>Gazebo/Blue</material>
  </gazebo>
  <gazebo reference="right_wheel_link">
    <material>Gazebo/Grey</material>
  </gazebo>
  <gazebo reference="left_wheel_link">
    <material>Gazebo/Grey</material>
  </gazebo>
  <gazebo reference="base_footprint">
    <material>Gazebo/Green</material>
  </gazebo>
  <gazebo reference="caster_wheel_link">
    <material>Gazebo/Grey</material>
  </gazebo>
</robot>
